[2023-11-15T08:57:01.267+0000] {taskinstance.py:1159} INFO - Dependencies all met for dep_context=non-requeueable deps ti=<TaskInstance: ETL_projet.create_table_urgences manual__2023-11-15T08:56:59.585947+00:00 [queued]>
[2023-11-15T08:57:01.271+0000] {taskinstance.py:1159} INFO - Dependencies all met for dep_context=requeueable deps ti=<TaskInstance: ETL_projet.create_table_urgences manual__2023-11-15T08:56:59.585947+00:00 [queued]>
[2023-11-15T08:57:01.271+0000] {taskinstance.py:1361} INFO - Starting attempt 1 of 1
[2023-11-15T08:57:01.277+0000] {taskinstance.py:1382} INFO - Executing <Task(PostgresOperator): create_table_urgences> on 2023-11-15 08:56:59.585947+00:00
[2023-11-15T08:57:01.284+0000] {standard_task_runner.py:57} INFO - Started process 1174 to run task
[2023-11-15T08:57:01.300+0000] {standard_task_runner.py:84} INFO - Running: ['***', 'tasks', 'run', 'ETL_projet', 'create_table_urgences', 'manual__2023-11-15T08:56:59.585947+00:00', '--job-id', '56', '--raw', '--subdir', 'DAGS_FOLDER/ETL_projet.py', '--cfg-path', '/tmp/tmp2xz81vmm']
[2023-11-15T08:57:01.302+0000] {standard_task_runner.py:85} INFO - Job 56: Subtask create_table_urgences
[2023-11-15T08:57:01.335+0000] {task_command.py:416} INFO - Running <TaskInstance: ETL_projet.create_table_urgences manual__2023-11-15T08:56:59.585947+00:00 [running]> on host 48045a1653b9
[2023-11-15T08:57:01.381+0000] {taskinstance.py:1662} INFO - Exporting env vars: AIRFLOW_CTX_DAG_OWNER='a***' AIRFLOW_CTX_DAG_ID='ETL_projet' AIRFLOW_CTX_TASK_ID='create_table_urgences' AIRFLOW_CTX_EXECUTION_DATE='2023-11-15T08:56:59.585947+00:00' AIRFLOW_CTX_TRY_NUMBER='1' AIRFLOW_CTX_DAG_RUN_ID='manual__2023-11-15T08:56:59.585947+00:00'
[2023-11-15T08:57:01.384+0000] {sql.py:274} INFO - Executing: CREATE TABLE IF NOT EXISTS urgences_covid (
    id serial PRIMARY KEY,
    dep INT REFERENCES departments_region(num_dep_int),
    date_de_passage DATE,
    sursaud_cl_age_corona INT REFERENCES tranche_age(Code),
    nbre_pass_corona INT,
    nbre_pass_tot INT,
    nbre_hospit_corona INT,
    nbre_pass_corona_h INT,
    nbre_pass_corona_f INT,
    nbre_pass_tot_h INT,
    nbre_pass_tot_f INT,
    nbre_hospit_corona_h INT,
    nbre_hospit_corona_f INT
);
[2023-11-15T08:57:01.389+0000] {base.py:73} INFO - Using connection ID 'postgres_connexion' for task execution.
[2023-11-15T08:57:01.393+0000] {base.py:73} INFO - Using connection ID 'postgres_connexion' for task execution.
[2023-11-15T08:57:01.403+0000] {sql.py:418} INFO - Running statement: CREATE TABLE IF NOT EXISTS urgences_covid (
    id serial PRIMARY KEY,
    dep INT REFERENCES departments_region(num_dep_int),
    date_de_passage DATE,
    sursaud_cl_age_corona INT REFERENCES tranche_age(Code),
    nbre_pass_corona INT,
    nbre_pass_tot INT,
    nbre_hospit_corona INT,
    nbre_pass_corona_h INT,
    nbre_pass_corona_f INT,
    nbre_pass_tot_h INT,
    nbre_pass_tot_f INT,
    nbre_hospit_corona_h INT,
    nbre_hospit_corona_f INT
);, parameters: None
[2023-11-15T08:57:01.410+0000] {taskinstance.py:1937} ERROR - Task failed with exception
Traceback (most recent call last):
  File "/home/airflow/.local/lib/python3.8/site-packages/airflow/providers/common/sql/operators/sql.py", line 280, in execute
    output = hook.run(
  File "/home/airflow/.local/lib/python3.8/site-packages/airflow/providers/common/sql/hooks/sql.py", line 392, in run
    self._run_command(cur, sql_statement, parameters)
  File "/home/airflow/.local/lib/python3.8/site-packages/airflow/providers/common/sql/hooks/sql.py", line 423, in _run_command
    cur.execute(sql_statement)
psycopg2.errors.UndefinedTable: relation "departments_region" does not exist

[2023-11-15T08:57:01.415+0000] {taskinstance.py:1400} INFO - Marking task as FAILED. dag_id=ETL_projet, task_id=create_table_urgences, execution_date=20231115T085659, start_date=20231115T085701, end_date=20231115T085701
[2023-11-15T08:57:01.424+0000] {standard_task_runner.py:104} ERROR - Failed to execute job 56 for task create_table_urgences (relation "departments_region" does not exist
; 1174)
[2023-11-15T08:57:01.432+0000] {local_task_job_runner.py:228} INFO - Task exited with return code 1
[2023-11-15T08:57:01.444+0000] {taskinstance.py:2778} INFO - 0 downstream tasks scheduled from follow-on schedule check
